Workbook

Sheet 全校113學年度授課節數比較表
B1: 全校113-114學年度授課節數概算表
B2: 學年度 | C2: 113學年度 | G2: 113學年度 | K2: 114學年度 | O2: 未來正式教師預估節數 | P2: 全校 需求 節數 | Q2: 剩餘 節數 | R2: 平均兼課節數 | U2: 未來尚可聘用人數 | V2: 113學年度日間職務編制 | AJ2: 代理人員備註 | AK2: 進修部授課為主之正式教師數 | AL2: 全校正式教師清單(綠字：主任、紫字：組長、藍字：科主任、粉字：導師、棕字：專任教師、底線黑字：進修部授課為主教師) | AM2: 進修部授課為主代理教師數 | AN2: 備註(人) | AO2: 備註(事) | AQ2: 應英科如調整應日科 | AR2: 應英科如調整特招班、會計科如調整國貿科 | AS2: 退休預估(人事室預先調查資料)
B3: 教學領域 | C3: 基本節數(正式教師以導師預估) | D3: 需求 節數 | E3: 剩餘 節數 | F3: 教師平均超時 | G3: 113學年職務正式教師節數 | H3: 需求 節數 | I3: 剩餘 節數 | J3: 正式教師平均超時 | K3: 114學年職務正式教師節數(以導師預估) | L3: 需求 節數 | M3: 剩餘 節數 | N3: 正式教師平均超時 | R3: 108學年度 節/人 | S3: 109學年度 節/人 | T3: 110學年度 節/人 | V3: 職稱 | W3: 主任 | X3: 組長 | Z3: 科主任 | AB3: 導師/資源教室業務/召集人 | AE3: 專任 | AH3: 人員合 計 | AI3: 基本授課 時數
V4: 基本 時數 | W4: 1 | X4: 5 | Y4: 7 | Z4: 6 | AA4: 7 | AB4: 10 | AC4: 12 | AD4: 14 | AE4: 12 | AF4: 14 | AG4: 16
B5: 國文/ 社會領域 | C5: =(AH5+AK5)*10 -> 130 | D5: =日113課程節數預估表!AH5-9+進113課程節數一覽表!K4 -> 132 | E5: =D5-C5 -> 2 | F5: =E5/(AH5+AK5) -> 0.15384615 | G5: =AI5+26 -> 104 | H5: =D5 -> 132 | I5: =H5-G5 -> 28 | J5: =I5/(AH5+AK5) -> 2.1538462 | K5: =C5 -> 130 | L5: =日114課程節數預估表!AJ5-9+進113課程節數一覽表!K4 -> 146 | M5: =L5-K5 -> 16 | N5: =M5/(AH5+AK5) -> 1.2307692 | O5: =(AH5+AK5)*10 -> 130 | P5: =L5 -> 146 | Q5: =P5-O5 -> 16 | R5: 6.2 | S5: 6.6 | T5: =#REF!/(AH5-#REF!) -> #REF! | U5: 0 | V5: 各 科 教 師 人 數 | W5: 3 | Y5: 1 | AB5: 4 | AF5: 2 | AH5: =SUM(W5:AG5) -> 10 | AI5: =W5*$W$4+X5*$X$4+Y5*$Y$4+Z5*$Z$4+AA5*$AA$4+AB5*$AB$4+AC5*$AC$4+AD5*$AD$4+AE5*$AE$4+AF5*$AF$4+AG5*$AG$4 -> 78 | AJ5: 不含代理教師廖懿琳 | AK5: 3 | AL5: 邱亦縈、賴士鈞、呂善成、林怡菁、凌兆鳳、周宜梅、甘芝如、林淑萍、洪唯婷、陳維德、顏如玉、許雅婷、李智淵 | AM5: 0 | AO5: 113學年日校歷史、地理因應課綱挪移暫減14節
B6: 英文暨 應英科 | C6: =(AH6+AK6)*12 -> 132 | D6: =日113課程節數預估表!AI14+進113課程節數一覽表!K12 -> 141 | E6: =D6-C6 -> 9 | F6: =E6/(AH6+AK6) -> 0.81818182 | G6: =AI6+12 -> 128 | H6: =D6 -> 141 | I6: =H6-G6 -> 13 | J6: =I6/(AH6+AK6) -> 1.1818182 | K6: =C6 -> 132 | L6: =日114課程節數預估表!AK14+進113課程節數一覽表!K12 -> 143 | M6: =L6-K6 -> 11 | N6: =M6/(AH6+AK6) -> 1 | O6: =(AH6+AK6)*12 -> 132 | P6: =L6 -> 143 | Q6: =P6-O6 -> 11 | R6: -0.8 | S6: 1.2 | T6: =#REF!/(AH6-#REF!) -> #REF! | U6: *1 | X6: 1 | AA6: 1 | AC6: 6 | AG6: 2 | AH6: =SUM(W6:AG6) -> 10 | AI6: =W6*$W$4+X6*$X$4+Y6*$Y$4+Z6*$Z$4+AA6*$AA$4+AB6*$AB$4+AC6*$AC$4+AD6*$AD$4+AE6*$AE$4+AF6*$AF$4+AG6*$AG$4 -> 116 | AJ6: 不含代理教師蔡文杰 | AK6: 1 | AL6: 林美儒、康騰芳、張佑丞、余沛晴、王賢正、蘇孟珠、陳美惠、張敏慧、林宥均、張萬華、李濟森 | AM6: 1 | AN6: 113學年李濟森老師請侍親留停 | AQ6: 115學年減4節.116學年減10節.117學年減7節 | AS6: 114學年1人
B7: 數學領域 | C7: =(AH7+AK7)*12 -> 72 | D7: =日113課程節數預估表!AH37+進113課程節數一覽表!K14 -> 100 | E7: =D7-C7 -> 28 | F7: =E7/(AH7+AK7) -> 4.6666667 | G7: =AI7 -> 57 | H7: =D7 -> 100 | I7: =H7-G7 -> 43 | J7: =I7/(AH7+AK7) -> 7.1666667 | K7: =C7 -> 72 | L7: =日114課程節數預估表!AJ37+進113課程節數一覽表!K14 -> 100 | M7: =L7-K7 -> 28 | N7: =M7/(AH7+AK7) -> 4.6666667 | O7: =(AH7+AK7)*12 -> 72 | P7: =L7 -> 100 | Q7: =P7-O7 -> 28 | R7: 4.125 | S7: 0.75 | T7: =#REF!/(AH7-#REF!) -> #REF! | U7: 1 | X7: 1 | AC7: 3 | AG7: 1 | AH7: 6 | AI7: =W7*$W$4+X7*$X$4+Y7*$Y$4+Z7*$Z$4+AA7*$AA$4+AB7*$AB$4+AC7*$AC$4+AD7*$AD$4+AE7*$AE$4+AF7*$AF$4+AG7*$AG$4 -> 57 | AJ7: 不含代理教師林秋美、楊昌融 | AK7: 0 | AL7: 陳威任、吳汶諭(留停)、李振巽、葉士瑋、林俊儒、高淩鈴 | AM7: 0 | AN7: 113學年吳汶諭老師請育嬰留停
B8: 自然領域 | C8: =AI8 -> 16 | D8: =日113課程節數預估表!AH41+進113課程節數一覽表!K68 -> 22 | E8: =D8-C8 -> 6 | F8: =E8/(AH8+AK8) -> 6 | G8: =AI8 -> 16 | H8: =D8 -> 22 | I8: =H8-G8 -> 6 | J8: =I8/(AH8+AK8) -> 6 | K8: =C8 -> 16 | L8: =日114課程節數預估表!AJ41+進113課程節數一覽表!K68 -> 22 | M8: =L8-K8 -> 6 | N8: =M8/(AH8+AK8) -> 6 | O8: =(AH8+AK8)*12 -> 12 | P8: =L8 -> 22 | Q8: =P8-O8 -> 10 | R8: 6 | S8: 6 | T8: =#REF!/(AH8-#REF!) -> #REF! | U8: 0 | AG8: 1 | AH8: =SUM(W8:AG8) -> 1 | AI8: =W8*$W$4+X8*$X$4+Y8*$Y$4+Z8*$Z$4+AA8*$AA$4+AB8*$AB$4+AC8*$AC$4+AD8*$AD$4+AE8*$AE$4+AF8*$AF$4+AG8*$AG$4 -> 16 | AK8: 0 | AL8: 楊宜升 | AM8: 0
B9: 資處科 | C9: =(AH9+AK9)*12-9-7 -> 116 | D9: =日113課程節數預估表!AI82+進113課程節數一覽表!K42 -> 150 | E9: =D9-C9 -> 34 | F9: =E9/(AH9+AK9) -> 3.0909091 | G9: =AI9+35 -> 83 | H9: =D9 -> 150 | I9: =H9-G9 -> 67 | J9: =I9/(AH9+AK9) -> 6.0909091 | K9: =C9 -> 116 | L9: =日114課程節數預估表!AK82+進113課程節數一覽表!K42 -> 138 | M9: =L9-K9 -> 22 | N9: =M9/(AH9+AK9) -> 2 | O9: =(AH9+AK9)*12 -> 132 | P9: =L9 -> 138 | Q9: =P9-O9 -> 6 | R9: 4 | S9: 6 | T9: =#REF!/(AH9-#REF!) -> #REF! | U9: *1 | W9: 2 | X9: 1 | Y9: 2 | Z9: 1 | AC9: 1 | AG9: 1 | AH9: =SUM(W9:AG9) -> 8 | AI9: =(W9*$W$4+X9*$X$4+Y9*$Y$4+Z9*$Z$4+AA9*$AA$4+AB9*$AB$4+AC9*$AC$4+AD9*$AD$4+AE9*$AE$4+AF9*$AF$4+AG9*$AG$4)-7 -> 48 | AJ9: 不含代理教師楊文鶯、陳美娟、張德彥；許志恒老師兼授公民 | AK9: 3 | AL9: 陳麴合、黃蘭芝、陳妙紅、陳月梅、許志恆、曹琮閔、張正芳、江素慧、吳振銘(進)、官孟璋、張美惠、劉和師 | AM9: 0 | AN9: 許志恆教師兼授公民 | AO9: 113學年有實用技能班一班(高一)共4節、資媒組長綁定資料處理科 | AS9: 114學年1人、116學年1人
B10: 會計科 | C10: =(AH10+AK10)*12 -> 108 | D10: =日113課程節數預估表!AH44+進113課程節數一覽表!K15 -> 142 | E10: =D10-C10 -> 34 | F10: =E10/(AH10+AK10) -> 3.7777778 | G10: =AI10+12 -> 100 | H10: =D10 -> 142 | I10: =H10-G10 -> 42 | J10: =I10/(AH10+AK10) -> 4.6666667 | K10: =C10 -> 108 | L10: =日114課程節數預估表!AJ44+進113課程節數一覽表!K15 -> 141 | M10: =L10-K10 -> 33 | N10: =M10/(AH10+AK10) -> 3.6666667 | O10: =(AH10+AK10)*12 -> 108 | P10: =L10 -> 141 | Q10: =P10-O10 -> 33 | R10: 2.8888889 | S10: 2 | T10: =#REF!/(AH10-#REF!) -> #REF! | U10: 1 | W10: 1 | AA10: 1 | AC10: 4 | AG10: 2 | AH10: =SUM(W10:AG10) -> 8 | AI10: =W10*$W$4+X10*$X$4+Y10*$Y$4+Z10*$Z$4+AA10*$AA$4+AB10*$AB$4+AC10*$AC$4+AD10*$AD$4+AE10*$AE$4+AF10*$AF$4+AG10*$AG$4 -> 88 | AJ10: 不含代理教師林坤宏、黃伃延 | AK10: 1 | AL10: 江曾為美、施美言、林淑滿、歐郁玟、陳學毅、周碧純、烏莎斯、謝淑姿、黃文華 | AM10: 1 | AO10: 113學年有實用技能班一班(高一)共3節
B11: 商經科 | C11: =(AH11+AK11)*12 -> 120 | D11: =日113課程節數預估表!AH63+進113課程節數一覽表!K28 -> 151 | E11: =D11-C11 -> 31 | F11: =E11/(AH11+AK11) -> 3.1 | G11: =AI11+12 -> 107 | H11: =D11 -> 151 | I11: =H11-G11 -> 44 | J11: =I11/(AH11+AK11) -> 4.4 | K11: =C11 -> 120 | L11: =日114課程節數預估表!AJ63+進113課程節數一覽表!K28 -> 146 | M11: =L11-K11 -> 26 | N11: =M11/(AH11+AK11) -> 2.6 | O11: =(AH11+AK11)*12 -> 120 | P11: =L11 -> 146 | Q11: =P11-O11 -> 26 | R11: 2 | S11: 4.33 | T11: =#REF!/(AH11-#REF!) -> #REF! | U11: 1 | X11: 1 | Y11: 1 | AA11: 1 | AC11: 5 | AG11: 1 | AH11: =SUM(W11:AG11) -> 9 | AI11: =W11*$W$4+X11*$X$4+Y11*$Y$4+Z11*$Z$4+AA11*$AA$4+AB11*$AB$4+AC11*$AC$4+AD11*$AD$4+AE11*$AE$4+AF11*$AF$4+AG11*$AG$4 -> 95 | AJ11: 不含代理教師李思穎 | AK11: 1 | AL11: 林宣融、許雅婷、李翠華、魏彙菁、沈恩典、林淑芬、林秀峯、洪慧珊、粘雅琪、張秋菊 | AM11: 1 | AO11: 113學年有實用技能班一班(高一)共5節
B12: 多媒科 | C12: =AI12 -> 20 | D12: =日113課程節數預估表!AH104 -> 26 | E12: =D12-C12 -> 6 | F12: =E12/(AH12+AK12) -> 3 | G12: =AI12 -> 20 | H12: =D12 -> 26 | I12: =H12-G12 -> 6 | J12: =I12/(AH12+AK12) -> 3 | K12: =C12 -> 20 | L12: =日114課程節數預估表!AK103 -> 45 | M12: =L12-K12 -> 25 | N12: =M12/(AH12+AK12) -> 12.5 | O12: =(AH12+AK12)*12 -> 24 | P12: =L12 -> 45 | Q12: =P12-O12 -> 21 | U12: *2 | AB12: 2 | AH12: =SUM(W12:AG12) -> 2 | AI12: 20 | AK12: 0 | AL12: 蔡雅雯、江亭儀(特教業務) | AM12: 0
B13: 藝術生活/ 美術 | C13: =AI13 -> 0 | D13: =日113課程節數預估表!AH122+進113課程節數一覽表!K63 -> 21 | E13: =D13-C13 -> 21 | G13: =AI13 -> 0 | H13: =D13 -> 21 | I13: =H13-G13 -> 21 | K13: =C13 -> 0 | L13: =日114課程節數預估表!AJ134+進113課程節數一覽表!J63 -> 22 | M13: =L13-K13 -> 22 | O13: =(AH13+AK13)*12 -> 0 | P13: =L13 -> 22 | Q13: =P13-O13 -> 22 | R13: 18 | S13: 2 | T13: =#REF!/(AH13-#REF!) -> #REF! | U13: 1 | AH13: =SUM(W13:AG13) -> 0 | AI13: =W13*$W$4+X13*$X$4+Y13*$Y$4+Z13*$Z$4+AA13*$AA$4+AB13*$AB$4+AC13*$AC$4+AD13*$AD$4+AE13*$AE$4+AF13*$AF$4+AG13*$AG$4 -> 0 | AJ13: 不含代理教師廖婕雅 | AK13: 0 | AM13: 0
B14: 體 育 | C14: =AH14*12 -> 48 | D14: =日113課程節數預估表!AH124+進113課程節數一覽表!J70+進113課程節數一覽表!J71 -> 61 | E14: =D14-C14 -> 13 | F14: =E14/(AH14+AK14) -> 2.6 | G14: =AI14 -> 43 | H14: =D14 -> 61 | I14: =H14-G14 -> 18 | J14: =I14/(AH14+AK14) -> 3.6 | K14: =C14 -> 48 | L14: =日114課程節數預估表!AJ136+進113課程節數一覽表!J70+進113課程節數一覽表!J71 -> 61 | M14: =L14-K14 -> 13 | N14: =M14/(AH14+AK14) -> 2.6 | O14: =(AH14+AK14)*12 -> 60 | P14: =L14 -> 61 | Q14: =P14-O14 -> 1 | R14: 5.5 | S14: 5.5 | T14: =#REF!/(AH14-#REF!) -> #REF! | U14: 0 | Y14: 1 | AC14: 3 | AH14: =SUM(W14:AG14) -> 4 | AI14: =W14*$W$4+X14*$X$4+Y14*$Y$4+Z14*$Z$4+AA14*$AA$4+AB14*$AB$4+AC14*$AC$4+AD14*$AD$4+AE14*$AE$4+AF14*$AF$4+AG14*$AG$4 -> 43 | AJ14: 不含代理教師莊明璋 | AK14: 1 | AL14: 田德洋、丁瑋君、王曉琪、王淑華 | AM14: 0
B15: 健康與護理/ 生涯規劃 | C15: 12 | D15: =日113課程節數預估表!AH125+日113課程節數預估表!AH127+進113課程節數一覽表!J65+進113課程節數一覽表!J72+進113課程節數一覽表!J73 -> 34 | E15: =D15-C15 -> 22 | G15: 7 | H15: =D15 -> 34 | I15: =H15-G15 -> 27 | K15: =C15 -> 12 | L15: =日114課程節數預估表!AJ137+日114課程節數預估表!AJ139+進113課程節數一覽表!J65+進113課程節數一覽表!J72+進113課程節數一覽表!J73 -> 25 | M15: =L15-K15 -> 13 | O15: 12 | P15: =L15 -> 25 | Q15: =P15-O15 -> 13 | R15: 0.66666667 | S15: -1.33 | T15: =#REF!/(AH15-#REF!) -> #REF! | U15: 0 | W15: 1 | X15: 1 | Y15: 1 | AH15: =SUM(W15:AG15) -> 3 | AI15: =W15*$W$4+X15*$X$4+Y15*$Y$4+Z15*$Z$4+AA15*$AA$4+AB15*$AB$4+AC15*$AC$4+AD15*$AD$4+AE15*$AE$4+AF15*$AF$4+AG15*$AG$4 -> 13 | AJ15: 不含代理教師蘇文夙 | AK15: 1 | AL15: 阮珊珊、朱湄惠、林明穎、黃佩莉 | AM15: 0 | AO15: 113學年日生涯規劃因課綱調整生涯規劃暫多9節 | AS15: 116學年1人
B16: 全民國防教育 | D16: =9+進113課程節數一覽表!J73 -> 11 | E16: 9 | H16: =D16 -> 11 | I16: 9 | L16: =9+進113課程節數一覽表!J73 -> 11 | O16: 0 | P16: =L16 -> 11 | Q16: =P16-O16 -> 11 | R16: -2 | S16: -4.25 | T16: =#REF!/(AH16-#REF!) -> #REF! | U16: *1 | AI16: =W16*$W$4+X16*$X$4+Y16*$Y$4+Z16*$Z$4+AA16*$AA$4+AB16*$AB$4+AC16*$AC$4+AD16*$AD$4+AE16*$AE$4+AF16*$AF$4+AG16*$AG$4 -> 0 | AJ16: 招聘代理教師，若無則請教官支援 | AK16: 1 | AL16: 軍訓教官支援(尚有3人，惟將於113學年退伍1人、114學年退伍1人) | AM16: 0
W18: =SUM(W5:W16) -> 7 | X18: =SUM(X5:X16) -> 5 | Y18: =SUM(Y5:Y16) -> 6 | Z18: =SUM(Z5:Z16) -> 1 | AA18: =SUM(AA5:AA16) -> 3 | AB18: =SUM(AB5:AB16) -> 6 | AC18: =SUM(AC5:AC16) -> 22 | AD18: =SUM(AD5:AD16) -> 0 | ... AH18: =SUM(AH5:AH16) -> 61
AD19: 含：資源教室業務及導師

Sheet 日113課程節數預估表
B1: 113學年度本校課程節數一覽表--日校 | G1: 適用課綱：111(高三)、112(高二)、113(高一)
B2: 教學 領域 | C2: 科 目 名 稱 | D2: 一 年 級 | N2: 二 年 級 | X2: 三 年 級 | AF2: 小 計 | AH2: 各領域 總 計
D3: 多媒科 | F3: 資處科 | H3: 會計科 | J3: 商經科 | L3: 應英科 | N3: 多媒科 | P3: 資處科 | R3: 會計科 | T3: 商經科 | V3: 應英科 | X3: 資處科 | Z3: 會計科 | AB3: 商經科 | AD3: 應英科
D4: 上 | E4: 下 | F4: 上 | G4: 下 | H4: 上 | I4: 下 | J4: 上 | K4: 下 | L4: 上 | M4: 下 | N4: 上 | O4: 下 | P4: 上 | Q4: 下 | R4: 上 | S4: 下 | T4: 上 | U4: 下 | V4: 上 | W4: 下 | X4: 上 | Y4: 下 | Z4: 上 | AA4: 下 | AB4: 上 | AC4: 下 | AD4: 上 | AE4: 下 | AF4: 上 | AG4: 下 | AH4: 上 | AI4: 下
B5: 國文/ 社會 | C5: 國語文 | D5: 3 | E5: 3 | F5: 3 | G5: 3 | H5: 3 | I5: 3 | J5: 3 | K5: 3 | L5: 3 | M5: 3 | N5: 3 | O5: 3 | P5: 3 | Q5: 3 | R5: 3 | S5: 3 | T5: 3 | U5: 3 | V5: 3 | W5: 3 | X5: 2 | Y5: 2 | Z5: 2 | AA5: 2 | AB5: 2 | AC5: 2 | AD5: 2 | AE5: 2 | AF5: =F5*2+H5*2+J5*2+L5*2+P5*2+R5*2+T5*2+V5*2+X5*3+Z5*2+AB5*2+AD5*2+D5+N5 -> 72 | AG5: =G5*2+I5*2+K5*2+M5*2+Q5*2+S5*2+U5*2+W5*2+Y5*3+AA5*2+AC5*2+AE5*2+E5+O5 -> 72 | AH5: =SUM(AF5:AF13) -> 112 | AI5: =SUM(AG5:AG13) -> 116
C6: 古典文學選讀 | D6: 1 | E6: 1 | F6: 1 | G6: 1 | H6: 1 | I6: 1 | J6: 1 | K6: 1 | L6: 1 | M6: 1 | AF6: =F6*2+H6*2+J6*2+L6*2+P6*3+R6*2+T6*2+V6*2+X6*3+Z6*2+AB6*2+AD6*2+D6 -> 9 | AG6: =G6*2+I6*2+K6*2+M6*2+Q6*3+S6*2+U6*2+W6*2+Y6*3+AA6*2+AC6*2+AE6*2+E6 -> 9
C7: 跨領域趨勢閱讀 | X7: 1 | Y7: 1 | Z7: 1 | AA7: 1 | AB7: 1 | AC7: 1 | AD7: 1 | AE7: 1 | AF7: =F7*3+H7*2+J7*2+L7*2+P7*3+R7*2+T7*2+V7*2+X7*3+Z7*2+AB7*2+AD7*2 -> 9 | AG7: =G7*3+I7*2+K7*2+M7*2+Q7*3+S7*2+U7*2+W7*2+Y7*3+AA7*2+AC7*2+AE7*2 -> 9
C8: 現代詩文賞析 | N8: 1 | O8: 1 | P8: 1 | Q8: 1 | R8: 1 | S8: 1 | T8: 1 | U8: 1 | V8: 1 | W8: 1 | AF8: =P8*2+R8*2+T8*2+V8*2+X8*3+Z8*2+AB8*2+AD8*2+N8 -> 9 | AG8: =Q8*2+S8*2+U8*2+W8*2+O8 -> 9
C9: 歷史(112起移至高三) | AF9: =P9*2+R9*2+T9*2+V9*2+N9 -> 0 | AG9: =Q9*2+S9*2+U9*2+W9*2+N9 -> 0
C10: 地理(多.資.英112起移至高三) | R10: 1 | S10: 1 | T10: 1 | U10: 1 | AF10: =P10*2+R10*2+T10*2+V10*2+N10 -> 4 | AG10: =Q10*2+S10*2+U10*2+W10*2+O10 -> 4
C11: 公民與社會 | X11: 1 | Y11: 1 | Z11: 1 | AA11: 1 | AB11: 1 | AC11: 1 | AD11: 1 | AE11: 1 | AF11: =X11*3+Z11*2+AB11*2+AD11*2 -> 9 | AG11: =Y11*3+AA11*2+AC11*2+AE11*2 -> 9
C12: 說故事學行銷(AP選) 3選1 | U12: 2 | AF12: 0 | AG12: 2
C13: 人工智慧溝通入門(AM選) 5選1 | S13: 2 | W13: 2 | AF13: 0 | AG13: 2 | AL13: 上學期 | AM13: 下學期
B14: 英文 | C14: 英語文 | D14: 2 | E14: 2 | F14: 2 | G14: 2 | H14: 2 | I14: 2 | J14: 2 | K14: 2 | L14: 2 | M14: 2 | N14: 2 | O14: 2 | P14: 2 | Q14: 2 | R14: 2 | S14: 2 | T14: 2 | U14: 2 | V14: 2 | W14: 2 | X14: 2 | Y14: 2 | Z14: 2 | AA14: 2 | AB14: 2 | AC14: 2 | AD14: 2 | AE14: 2 | AF14: =F14*2+H14*2+J14*2+L14*2+P14*2+R14*2+T14*2+V14*2+X14*3+Z14*2+AB14*2+AD14*2+D14+N14 -> 54 | AG14: =G14*2+I14*2+K14*2+M14*2+Q14*2+S14*2+U14*2+W14*2+Y14*3+AA14*2+AC14*2+AE14*2+E14+O14 -> 54 | AH14: =SUM(AF14:AF36)-2 -> 137 | AI14: =SUM(AG14:AG36) -> 127 | AK14: 普通科節數 | AL14: =AF14+AF15+AF22+AF25 -> 89 | AM14: 89
C15: 生活英語會話 | D15: 1 | E15: 1 | F15: 1 | G15: 1 | H15: 1 | I15: 1 | J15: 1 | K15: 1 | AF15: =F15*2+H15*2+J15*2+D15 -> 7 | AG15: =G15*2+I15*2+K15*2+E15 -> 7 | AK15: 應用英語科節數 | AL15: =AH14-AL14 -> 48 | AM15: =AI14-AM14 -> 38
C16: 初階英語聽講練習 | L16: 2 | M16: 2 | AF16: =F16*3+H16*2+J16*2+L16*2+P16*3+R16*2+T16*2+V16*2+X16*3+Z16*2+AB16*2+AD16*2 -> 4 | AG16: =G16*3+I16*2+K16*2+M16*2+Q16*3+S16*2+U16*2+W16*2+Y16*3+AA16*2+AC16*2+AE16*2 -> 4
C17: 初階英文閱讀與寫作練習 | L17: 2 | M17: 2 | AF17: =F17*3+H17*2+J17*2+L17*2+P17*3+R17*2+T17*2+V17*2+X17*3+Z17*2+AB17*2+AD17*2 -> 4 | AG17: =G17*3+I17*2+K17*2+M17*2+Q17*3+S17*2+U17*2+W17*2+Y17*3+AA17*2+AC17*2+AE17*2 -> 4
C18: 中階英語聽講練習 | V18: 2 | W18: 2 | AF18: =F18*3+H18*2+J18*2+L18*2+P18*3+R18*2+T18*2+V18*2+X18*3+Z18*2+AB18*2+AD18*2 -> 4 | AG18: =G18*3+I18*2+K18*2+M18*2+Q18*3+S18*2+U18*2+W18*2+Y18*3+AA18*2+AC18*2+AE18*2 -> 4
C19: 中階英文閱讀與寫作練習 | V19: 2 | W19: 2 | AF19: =F19*3+H19*2+J19*2+L19*2+P19*3+R19*2+T19*2+V19*2+X19*3+Z19*2+AB19*2+AD19*2 -> 4 | AG19: =G19*3+I19*2+K19*2+M19*2+Q19*3+S19*2+U19*2+W19*2+Y19*3+AA19*2+AC19*2+AE19*2 -> 4
C20: 高階英語聽講練習 | AD20: 2 | AE20: 2 | AF20: =F20*3+H20*2+J20*2+L20*2+P20*3+R20*2+T20*2+V20*2+X20*3+Z20*2+AB20*2+AD20*2 -> 4 | AG20: =G20*3+I20*2+K20*2+M20*2+Q20*3+S20*2+U20*2+W20*2+Y20*3+AA20*2+AC20*2+AE20*2 -> 4
C21: 高階英文閱讀與寫作練習 | AD21: 2 | AE21: 2 | AF21: =F21*3+H21*2+J21*2+L21*2+P21*3+R21*2+T21*2+V21*2+X21*3+Z21*2+AB21*2+AD21*2 -> 4 | AG21: =G21*3+I21*2+K21*2+M21*2+Q21*3+S21*2+U21*2+W21*2+Y21*3+AA21*2+AC21*2+AE21*2 -> 4
C22: 基礎英文閱讀與寫作 | N22: 2 | O22: 2 | P22: 2 | Q22: 2 | R22: 2 | S22: 2 | T22: 2 | U22: 2 | AF22: =P22*2+R22*2+T22*2+N22 -> 14 | AG22: =Q22*2+S22*2+U22*2+O22 -> 14
C23: 英文商業書信寫作 | AD23: 2 | AF23: =F23*3+H23*2+J23*2+L23*2+P23*3+R23*2+T23*2+V23*2+X23*3+Z23*2+AB23*2+AD23*2 -> 4 | AG23: =G23*3+I23*2+K23*2+M23*2+Q23*3+S23*2+U23*2+W23*2+Y23*3+AA23*2+AC23*2+AE23*2 -> 0
C24: 英美文學作品賞析 | V24: 1 | AF24: =F24*3+H24*2+J24*2+L24*2+P24*3+R24*2+T24*2+V24*2+X24*3+Z24*2+AB24*2+AD24*2 -> 2 | AG24: =G24*3+I24*2+K24*2+M24*2+Q24*3+S24*2+U24*2+W24*2+Y24*3+AA24*2+AC24*2+AE24*2 -> 0
C25: 趣味英文閱讀 | X25: 2 | Y25: 2 | Z25: 2 | AA25: 2 | AB25: 2 | AC25: 2 | AF25: =X25*3+Z25*2+AB25*2 -> 14 | AG25: =Y25*3+AA25*2+AC25*2 -> 14
C26: 新聞英文導讀 | V26: 1 | AF26: =V26*2 -> 2 | AG26: 0
C27: 專題實作 | W27: 2 | AD27: 2 | AF27: =AD27*2 -> 4 | AG27: =AE27*2+W27*2 -> 4
C28: 外語簡報實務 | V28: 2 | W28: 2 | AF28: =V28*2 -> 4 | AG28: =W28*2 -> 4
C29: 實用英文表達(AM選)5選1 | S29: 2 | W29: 2 | AF29: =F29*3+H29*2+J29*2+L29*2+P29*3+R29*2+T29*2+V29*2+X29*3+Z29*2+AB29*2+AD29*2 -> 0 | AG29: 2
C30: 英語導覽(AL選)9選1 | P30: 2 | R30: 2 | T30: 2 | V30: 2 | AF30: 2 | AG30: 0
C31: 英語多媒體口說練習(AL選)9選1 | P31: 2 | R31: 2 | T31: 2 | V31: 2 | AF31: 2 | AG31: 0
C32: 繪本製作(AJ選)3選1 | V32: 2 | AF32: 2 | AG32: =G32*3+I32*2+K32*2+M32*2+Q32*3+S32*2+U32*2+W32*2+Y32*3+AA32*2+AC32*2+AE32*2 -> 0
C33: 英語電影欣賞與討論(AJ選)3選1 | V33: 2 | AF33: 2 | AG33: 0
C34: 英語桌遊(AJ選)3選1 | V34: 2 | AF34: 2 | AG34: 0
C35: 觀光餐旅英語(AG選)2選1 | AE35: 2 | AF35: =AD35*2 -> 0 | AG35: 2
C36: 英語導覽(AG選)2選1 | AE36: 2 | AF36: 0 | AG36: 2
B37: 數學/自然 | C37: 數學 | D37: 3 | E37: 3 | F37: 3 | G37: 3 | H37: 3 | I37: 3 | J37: 3 | K37: 3 | L37: 3 | M37: 3 | N37: 3 | O37: 3 | P37: 3 | Q37: 3 | R37: 3 | S37: 3 | T37: 3 | U37: 3 | V37: 3 | W37: 3 | AF37: =F37*2+H37*2+J37*2+L37*2+P37*3+R37*2+T37*2+V37*2+X37*3+Z37*2+AB37*2+AD37*2+D37 -> 54 | AG37: =G37*2+I37*2+K37*2+M37*2+Q37*3+S37*2+U37*2+W37*2+Y37*3+AA37*2+AC37*2+AE37*2+E37 -> 54 | AH37: =SUM(AF37:AF40) -> 90 | AI37: =SUM(AG37:AG40) -> 92
C38: 數學演習(移至高三) | X38: 1 | Y38: 1 | Z38: 1 | AA38: 1 | AB38: 1 | AC38: 1 | AD38: 1 | AE38: 1 | AF38: =F38*3+H38*2+J38*2+L38*2+P38*3+R38*2+T38*2+V38*2+X38*3+Z38*2+AB38*2+AD38*2 -> 9 | AG38: =G38*3+I38*2+K38*2+M38*2+Q38*3+S38*2+U38*2+W38*2+Y38*3+AA38*2+AC38*2+AE38*2 -> 9
C39: 數學應用 | X39: 3 | Y39: 3 | Z39: 3 | AA39: 3 | AB39: 3 | AC39: 3 | AD39: 3 | AE39: 3 | AF39: =F39*3+H39*2+J39*2+L39*2+P39*3+R39*2+T39*2+V39*2+X39*3+Z39*2+AB39*2+AD39*2 -> 27 | AG39: =G39*3+I39*2+K39*2+M39*2+Q39*3+S39*2+U39*2+W39*2+Y39*3+AA39*2+AC39*2+AE39*2 -> 27
C40: 趣味數學與遊戲(AM選) 5選1 | S40: 2 | W40: 2 | AF40: 0 | AG40: 2
...

Sheet 日114課程節數預估表
B1: 113學年度本校課程節數一覽表--日校 | G1: 適用課綱：112(高三)、113(高二)、114(高一)
B2: 教學 領域 | C2: 科 目 名 稱 | D2: 一 年 級 | N2: 二 年 級 | X2: 三 年 級 | AH2: 小 計 | AJ2: 各領域 總 計
D3: 多媒科 | F3: 資處科 | H3: 會計科 | J3: 商經科 | L3: 應英科 | N3: 多媒科 | P3: 資處科 | R3: 會計科 | T3: 商經科 | V3: 應英科 | X3: 多媒科 | Z3: 資處科 | AB3: 會計科 | AD3: 商經科 | AF3: 應英科
D4: 上 | E4: 下 | F4: 上 | G4: 下 | H4: 上 | I4: 下 | J4: 上 | K4: 下 | L4: 上 | M4: 下 | N4: 上 | O4: 下 | P4: 上 | Q4: 下 | R4: 上 | S4: 下 | T4: 上 | U4: 下 | V4: 上 | W4: 下 | X4: 上 | Y4: 下 | Z4: 上 | AA4: 下 | AB4: 上 | AC4: 下 | AD4: 上 | AE4: 下 | AF4: 上 | AG4: 下 | AH4: 上 | AI4: 下 | AJ4: 上 | AK4: 下
B5: 國文/ 社會 | C5: 國語文 | D5: 3 | E5: 3 | F5: 3 | G5: 3 | H5: 3 | I5: 3 | J5: 3 | K5: 3 | L5: 3 | M5: 3 | N5: 3 | O5: 3 | P5: 3 | Q5: 3 | R5: 3 | S5: 3 | T5: 3 | U5: 3 | V5: 3 | W5: 3 | X5: 2 | Y5: 2 | Z5: 2 | AA5: 2 | AB5: 2 | AC5: 2 | AD5: 2 | AE5: 2 | AF5: 2 | AG5: 2 | AH5: =F5*2+H5*2+J5*2+L5*2+P5*2+R5*2+T5*2+V5*2+Z5*2+AB5*2+AD5*2+AF5*2+D5+N5+X5 -> 72 | AI5: =G5*2+I5*2+K5*2+M5*2+Q5*2+S5*2+U5*2+W5*2+AA5*2+AC5*2+AE5*2+AG5*2+E5+O5+Y5 -> 72 | AJ5: =SUM(AH5:AH13) -> 126 | AK5: =SUM(AI5:AI13) -> 130
C6: 古典文學選讀 | D6: 1 | E6: 1 | F6: 1 | G6: 1 | H6: 1 | I6: 1 | J6: 1 | K6: 1 | L6: 1 | M6: 1 | AH6: =F6*2+H6*2+J6*2+L6*2+P6*3+R6*2+T6*2+V6*2+Z6*3+AB6*2+AD6*2+AF6*2+D6 -> 9 | AI6: =G6*2+I6*2+K6*2+M6*2+Q6*3+S6*2+U6*2+W6*2+AA6*3+AC6*2+AE6*2+AG6*2+E6 -> 9
C7: 跨領域趨勢閱讀 | X7: 1 | Y7: 1 | Z7: 1 | AA7: 1 | AB7: 1 | AC7: 1 | AD7: 1 | AE7: 1 | AF7: 1 | AG7: 1 | AH7: =F7*3+H7*2+J7*2+L7*2+P7*3+R7*2+T7*2+V7*2+Z7*2+AB7*2+AD7*2+AF7*2+X7 -> 9 | AI7: =G7*3+I7*2+K7*2+M7*2+Q7*3+S7*2+U7*2+W7*2+AA7*2+AC7*2+AE7*2+AG7*2+Y7 -> 9
C8: 現代詩文賞析 | N8: 1 | O8: 1 | P8: 1 | Q8: 1 | R8: 1 | S8: 1 | T8: 1 | U8: 1 | V8: 1 | W8: 1 | AH8: =P8*2+R8*2+T8*2+V8*2+Z8*3+AB8*2+AD8*2+AF8*2+N8 -> 9 | AI8: =Q8*2+S8*2+U8*2+W8*2+O8 -> 9
C9: 歷史(112起移至高三) | X9: 1 | Y9: 1 | Z9: 1 | AA9: 1 | AB9: 1 | AC9: 1 | AD9: 1 | AE9: 1 | AF9: 1 | AG9: 1 | AH9: =X9+Z9*2+AB9*2+AD9*2+AF9*2 -> 9 | AI9: =Y9+AA9*2+AC9*2+AE9*2+AG9*2 -> 9
C10: 地理(多.資.英112起移至高三) | R10: 1 | S10: 1 | T10: 1 | U10: 1 | X10: 1 | Y10: 1 | Z10: 1 | AA10: 1 | AF10: 1 | AG10: 1 | AH10: =P10*2+R10*2+T10*2+V10*2+N10+X10+Z10*2+AF10*2 -> 9 | AI10: =Q10*2+S10*2+U10*2+W10*2+O10+Y10+AA10*2+AG10*2 -> 9
C11: 公民與社會 | X11: 1 | Y11: 1 | Z11: 1 | AA11: 1 | AB11: 1 | AC11: 1 | AD11: 1 | AE11: 1 | AF11: 1 | AG11: 1 | AH11: =Z11*2+AB11*2+AD11*2+AF11*2+X11 -> 9 | AI11: =AA11*2+AC11*2+AE11*2+AG11*2+Y11 -> 9
C12: 說故事學行銷(AP選) 3選1 | U12: 2 | AH12: 0 | AI12: 2
C13: 人工智慧溝通入門(AM選) 5選1 | S13: 2 | W13: 2 | AH13: 0 | AI13: 2
B14: 英文 | C14: 英語文 | D14: 2 | E14: 2 | F14: 2 | G14: 2 | H14: 2 | I14: 2 | J14: 2 | K14: 2 | L14: 2 | M14: 2 | N14: 2 | O14: 2 | P14: 2 | Q14: 2 | R14: 2 | S14: 2 | T14: 2 | U14: 2 | V14: 2 | W14: 2 | X14: 2 | Y14: 2 | Z14: 2 | AA14: 2 | AB14: 2 | AC14: 2 | AD14: 2 | AE14: 2 | AF14: 2 | AG14: 2 | AH14: =F14*2+H14*2+J14*2+L14*2+P14*2+R14*2+T14*2+V14*2+Z14*2+AB14*2+AD14*2+AF14*2+D14+N14+X14 -> 54 | AI14: =G14*2+I14*2+K14*2+M14*2+Q14*2+S14*2+U14*2+W14*2+AA14*2+AC14*2+AE14*2+AG14*2+E14+O14+Y14 -> 54 | AJ14: =SUM(AH14:AH36)-2 -> 135 | AK14: =SUM(AI14:AI36) -> 129 | AN14: 上學期 | AO14: 下學期
C15: 生活英語會話 | D15: 1 | E15: 1 | F15: 1 | G15: 1 | H15: 1 | I15: 1 | J15: 1 | K15: 1 | AH15: =F15*2+H15*2+J15*2+D15 -> 7 | AI15: =G15*2+I15*2+K15*2+E15 -> 7 | AM15: 普通科節數 | AN15: =AH14+AH15+AH22+AH25 -> 89 | AO15: =AI14+AI15+AI22+AI25 -> 89
C16: 初階英語聽講練習 | L16: 2 | M16: 2 | AH16: =F16*3+H16*2+J16*2+L16*2+P16*3+R16*2+T16*2+V16*2+Z16*3+AB16*2+AD16*2+AF16*2 -> 4 | AI16: =G16*3+I16*2+K16*2+M16*2+Q16*3+S16*2+U16*2+W16*2+AA16*3+AC16*2+AE16*2+AG16*2 -> 4 | AM16: 應用英語科節數 | AN16: =AJ14-AN15 -> 46 | AO16: =AK14-AO15 -> 40
C17: 初階英文閱讀與寫作練習 | L17: 2 | M17: 2 | AH17: =F17*3+H17*2+J17*2+L17*2+P17*3+R17*2+T17*2+V17*2+Z17*3+AB17*2+AD17*2+AF17*2 -> 4 | AI17: =G17*3+I17*2+K17*2+M17*2+Q17*3+S17*2+U17*2+W17*2+AA17*3+AC17*2+AE17*2+AG17*2 -> 4
C18: 中階英語聽講練習 | V18: 2 | W18: 2 | AH18: =F18*3+H18*2+J18*2+L18*2+P18*3+R18*2+T18*2+V18*2+Z18*3+AB18*2+AD18*2+AF18*2 -> 4 | AI18: =G18*3+I18*2+K18*2+M18*2+Q18*3+S18*2+U18*2+W18*2+AA18*3+AC18*2+AE18*2+AG18*2 -> 4
C19: 中階英文閱讀與寫作練習 | V19: 2 | W19: 2 | AH19: =F19*3+H19*2+J19*2+L19*2+P19*3+R19*2+T19*2+V19*2+Z19*3+AB19*2+AD19*2+AF19*2 -> 4 | AI19: =G19*3+I19*2+K19*2+M19*2+Q19*3+S19*2+U19*2+W19*2+AA19*3+AC19*2+AE19*2+AG19*2 -> 4
C20: 高階英語聽講練習 | AF20: 2 | AG20: 2 | AH20: =F20*3+H20*2+J20*2+L20*2+P20*3+R20*2+T20*2+V20*2+Z20*3+AB20*2+AD20*2+AF20*2 -> 4 | AI20: =G20*3+I20*2+K20*2+M20*2+Q20*3+S20*2+U20*2+W20*2+AA20*3+AC20*2+AE20*2+AG20*2 -> 4
C21: 高階英文閱讀與寫作練習 | AF21: 2 | AG21: 2 | AH21: =F21*3+H21*2+J21*2+L21*2+P21*3+R21*2+T21*2+V21*2+Z21*3+AB21*2+AD21*2+AF21*2 -> 4 | AI21: =G21*3+I21*2+K21*2+M21*2+Q21*3+S21*2+U21*2+W21*2+AA21*3+AC21*2+AE21*2+AG21*2 -> 4
C22: 基礎英文閱讀與寫作 | N22: 2 | O22: 2 | P22: 2 | Q22: 2 | R22: 2 | S22: 2 | T22: 2 | U22: 2 | AH22: =P22*2+R22*2+T22*2+N22 -> 14 | AI22: =Q22*2+S22*2+U22*2+O22 -> 14
C23: 英文商業書信寫作 | AF23: 1 | AG23: 1 | AH23: =F23*3+H23*2+J23*2+L23*2+P23*3+R23*2+T23*2+V23*2+Z23*3+AB23*2+AD23*2+AF23*2 -> 2 | AI23: =G23*3+I23*2+K23*2+M23*2+Q23*3+S23*2+U23*2+W23*2+AA23*3+AC23*2+AE23*2+AG23*2 -> 2
C24: 英美文學作品賞析 | V24: 1 | AH24: =F24*3+H24*2+J24*2+L24*2+P24*3+R24*2+T24*2+V24*2+Z24*3+AB24*2+AD24*2+AF24*2 -> 2 | AI24: =G24*3+I24*2+K24*2+M24*2+Q24*3+S24*2+U24*2+W24*2+AA24*3+AC24*2+AE24*2+AG24*2 -> 0
C25: 趣味英文閱讀 | X25: 2 | Y25: 2 | Z25: 2 | AA25: 2 | AB25: 2 | AC25: 2 | AD25: 2 | AE25: 2 | AH25: =Z25*2+X25+AB25*2+AD25*2 -> 14 | AI25: =AA25*2+Y25+AC25*2+AE25*2 -> 14
C26: 新聞英文導讀 | V26: 1 | AH26: =V26*2 -> 2 | AI26: 0
C27: 專題實作 | W27: 2 | AF27: 2 | AH27: =AF27*2 -> 4 | AI27: =AG27*2+W27*2 -> 4
C28: 外語簡報實務 | V28: 2 | W28: 2 | AH28: =V28*2 -> 4 | AI28: =W28*2 -> 4
C29: 實用英文表達(AM選)5選1 | S29: 2 | W29: 2 | AH29: =F29*3+H29*2+J29*2+L29*2+P29*3+R29*2+T29*2+V29*2+Z29*3+AB29*2+AD29*2+AF29*2 -> 0 | AI29: 2
C30: 英語導覽(AL選)9選1 | P30: 2 | R30: 2 | T30: 2 | V30: 2 | AH30: 2 | AI30: 0
C31: 英語多媒體口說練習(AL選)9選1 | P31: 2 | R31: 2 | T31: 2 | V31: 2 | AH31: 2 | AI31: 0
C32: 繪本製作(AJ選)3選1 | V32: 2 | AH32: 2 | AI32: =G32*3+I32*2+K32*2+M32*2+Q32*3+S32*2+U32*2+W32*2+AA32*3+AC32*2+AE32*2+AG32*2 -> 0
C33: 英語電影欣賞與討論(AJ選)3選1 | V33: 2 | AH33: 2 | AI33: 0
C34: 職場英語情境練習(AJ選)3選1 | V34: 2 | AH34: 2 | AI34: 0
C35: 觀光餐旅英語(AG選)2選1 | AG35: 2 | AH35: =AF35*2 -> 0 | AI35: 2
C36: 中英翻譯練習(AG選)2選1 | AG36: 2 | AH36: 0 | AI36: 2
B37: 數學/自然 | C37: 數學 | D37: 3 | E37: 3 | F37: 3 | G37: 3 | H37: 3 | I37: 3 | J37: 3 | K37: 3 | L37: 3 | M37: 3 | N37: 3 | O37: 3 | P37: 3 | Q37: 3 | R37: 3 | S37: 3 | T37: 3 | U37: 3 | V37: 3 | W37: 3 | AH37: =F37*2+H37*2+J37*2+L37*2+P37*3+R37*2+T37*2+V37*2+Z37*3+AB37*2+AD37*2+AF37*2+D37 -> 54 | AI37: =G37*2+I37*2+K37*2+M37*2+Q37*3+S37*2+U37*2+W37*2+AA37*3+AC37*2+AE37*2+AG37*2+E37 -> 54 | AJ37: =SUM(AH37:AH40) -> 90 | AK37: =SUM(AI37:AI40) -> 92
C38: 數學演習(移至高三) | X38: 1 | Y38: 1 | Z38: 1 | AA38: 1 | AB38: 1 | AC38: 1 | AD38: 1 | AE38: 1 | AF38: 1 | AG38: 1 | AH38: =F38*3+H38*2+J38*2+L38*2+P38*3+R38*2+T38*2+V38*2+Z38*3+AB38*2+AD38*2+AF38*2 -> 9 | AI38: =G38*3+I38*2+K38*2+M38*2+Q38*3+S38*2+U38*2+W38*2+AA38*3+AC38*2+AE38*2+AG38*2 -> 9
C39: 數學應用 | X39: 3 | Y39: 3 | Z39: 3 | AA39: 3 | AB39: 3 | AC39: 3 | AD39: 3 | AE39: 3 | AF39: 3 | AG39: 3 | AH39: =F39*3+H39*2+J39*2+L39*2+P39*3+R39*2+T39*2+V39*2+Z39*3+AB39*2+AD39*2+AF39*2 -> 27 | AI39: =G39*3+I39*2+K39*2+M39*2+Q39*3+S39*2+U39*2+W39*2+AA39*3+AC39*2+AE39*2+AG39*2 -> 27
C40: 趣味數學與遊戲(AM選) 5選1 | S40: 2 | W40: 2 | AH40: 0 | AI40: 2
...

Sheet 112課程節數一覽表(商經科修改，橙色底深紅字)
B1: 112學年度本校課程節數一覽表--日校
B2: 教學 領域 | C2: 科 目 名 稱 | D2: 一 年 級 | N2: 二 年 級 | V2: 三 年 級 | AD2: 小 計 | AF2: 各領域 總 計
D3: 資處科 | F3: 會計科 | H3: 商經科 | J3: 應外科 | L3: 多媒科 | N3: 資處科 | P3: 會計科 | R3: 商經科 | T3: 應外科 | V3: 資處科 | X3: 會計科 | Z3: 商經科 | AB3: 應外科
D4: 上 | E4: 下 | F4: 上 | G4: 下 | H4: 上 | I4: 下 | J4: 上 | K4: 下 | L4: 上 | M4: 下 | N4: 上 | O4: 下 | P4: 上 | Q4: 下 | R4: 上 | S4: 下 | T4: 上 | U4: 下 | V4: 上 | W4: 下 | X4: 上 | Y4: 下 | Z4: 上 | AA4: 下 | AB4: 上 | AC4: 下 | AD4: 上 | AE4: 下 | AF4: 上 | AG4: 下
B5: 國文/ 社會 | C5: 國語文 | D5: 3 | E5: 3 | F5: 3 | G5: 3 | H5: 3 | I5: 3 | J5: 3 | K5: 3 | L5: 3 | M5: 3 | N5: 3 | O5: 3 | P5: 3 | Q5: 3 | R5: 3 | S5: 3 | T5: 3 | U5: 3 | V5: 2 | W5: 2 | X5: 2 | Y5: 2 | Z5: 2 | AA5: 2 | AB5: 2 | AC5: 2 | AD5: =D5*2+F5*2+H5*2+J5*2+N5*3+P5*2+R5*2+T5*2+V5*3+X5*2+Z5*2+AB5*2+L5 -> 72 | AE5: =E5*2+G5*2+I5*2+K5*2+O5*3+Q5*2+S5*2+U5*2+W5*3+Y5*2+AA5*2+AC5*2+M5 -> 72 | AF5: =SUM(AD5:AD14) -> 127 | AG5: =SUM(AE5:AE14) -> 131
C6: 古典文學選讀 | D6: 1 | E6: 1 | F6: 1 | G6: 1 | H6: 1 | I6: 1 | J6: 1 | K6: 1 | L6: 1 | M6: 1 | AD6: =D6*2+F6*2+H6*2+J6*2+N6*3+P6*2+R6*2+T6*2+V6*3+X6*2+Z6*2+AB6*2+L6 -> 9 | AE6: =E6*2+G6*2+I6*2+K6*2+O6*3+Q6*2+S6*2+U6*2+W6*3+Y6*2+AA6*2+AC6*2+M6 -> 9
C7: 紅樓夢飲食文化(AG選) 4選1 | S7: 2 | AD7: =D7*3+F7*2+H7*2+J7*2+N7*3+P7*2+R7*2+T7*2+V7*3+X7*2+Z7*2+AB7*2 -> 0 | AE7: 2
C8: 中國小說選 | V8: 1 | W8: 1 | X8: 1 | Y8: 1 | Z8: 1 | AA8: 1 | AB8: 1 | AC8: 1 | AD8: =D8*3+F8*2+H8*2+J8*2+N8*3+P8*2+R8*2+T8*2+V8*3+X8*2+Z8*2+AB8*2 -> 9 | AE8: =E8*3+G8*2+I8*2+K8*2+O8*3+Q8*2+S8*2+U8*2+W8*3+Y8*2+AA8*2+AC8*2 -> 9
C9: 閱讀趨勢理解時尚(AN選) 5選1 | Q9: 2 | U9: 2 | AD9: =D9*3+F9*2+H9*2+J9*2+N9*3+P9*2+R9*2+T9*2+V9*3+X9*2+Z9*2+AB9*2 -> 0 | AE9: 2
C10: 現代詩文賞析 | N10: 1 | O10: 1 | P10: 1 | Q10: 1 | R10: 1 | S10: 1 | T10: 1 | U10: 1 | AD10: =D10*3+F10*2+H10*2+J10*2+N10*3+P10*2+R10*2+T10*2+V10*3+X10*2+Z10*2+AB10*2 -> 9 | AE10: =E10*3+G10*2+I10*2+K10*2+O10*3+Q10*2+S10*2+U10*2+W10*3+Y10*2+AA10*2+AC10*2 -> 9
C11: 歷史 | N11: 1 | O11: 1 | P11: 1 | Q11: 1 | R11: 1 | S11: 1 | T11: 1 | U11: 1 | AD11: =D11*3+F11*2+H11*2+J11*2+N11*3+P11*2+R11*2+T11*2+V11*3+X11*2+Z11*2+AB11*2 -> 9 | AE11: =E11*3+G11*2+I11*2+K11*2+O11*3+Q11*2+S11*2+U11*2+W11*3+Y11*2+AA11*2+AC11*2 -> 9
C12: 地理 | N12: 1 | O12: 1 | P12: 1 | Q12: 1 | R12: 1 | S12: 1 | T12: 1 | U12: 1 | AD12: =D12*3+F12*2+H12*2+J12*2+N12*3+P12*2+R12*2+T12*2+V12*3+X12*2+Z12*2+AB12*2 -> 9 | AE12: =E12*3+G12*2+I12*2+K12*2+O12*3+Q12*2+S12*2+U12*2+W12*3+Y12*2+AA12*2+AC12*2 -> 9
C13: 國學萬花筒(彈性補強) | AD13: 1 | AE13: 1
C14: 公民與社會 | V14: 1 | W14: 1 | X14: 1 | Y14: 1 | Z14: 1 | AA14: 1 | AB14: 1 | AC14: 1 | AD14: =D14*3+F14*2+H14*2+J14*2+N14*3+P14*2+R14*2+T14*2+V14*3+X14*2+Z14*2+AB14*2 -> 9 | AE14: =E14*3+G14*2+I14*2+K14*2+O14*3+Q14*2+S14*2+U14*2+W14*3+Y14*2+AA14*2+AC14*2 -> 9
B15: 英文 | C15: 英語文 | D15: 2 | E15: 2 | F15: 2 | G15: 2 | H15: 2 | I15: 2 | J15: 2 | K15: 2 | L15: 2 | M15: 2 | N15: 2 | O15: 2 | P15: 2 | Q15: 2 | R15: 2 | S15: 2 | T15: 2 | U15: 2 | V15: 2 | W15: 2 | X15: 2 | Y15: 2 | Z15: 2 | AA15: 2 | AB15: 2 | AC15: 2 | AD15: =D15*2+F15*2+H15*2+J15*2+N15*3+P15*2+R15*2+T15*2+V15*3+X15*2+Z15*2+AB15*2+L15 -> 54 | AE15: =E15*2+G15*2+I15*2+K15*2+O15*3+Q15*2+S15*2+U15*2+W15*3+Y15*2+AA15*2+AC15*2+M15 -> 54 | AF15: =SUM(AD15:AD41) -> 140 | AG15: =SUM(AE15:AE41) -> 138
C16: 生活英語會話 | D16: 1 | E16: 1 | F16: 1 | G16: 1 | H16: 1 | I16: 1 | L16: 1 | M16: 1 | AD16: =D16*2+F16*2+H16*2+J16*2+N16*3+P16*2+R16*2+T16*2+V16*3+X16*2+Z16*2+AB16*2+L16 -> 7 | AE16: =E16*2+G16*2+I16*2+K16*2+O16*3+Q16*2+S16*2+U16*2+W16*3+Y16*2+AA16*2+AC16*2+M16 -> 7
C17: 初階英語聽講練習 | J17: 2 | K17: 2 | AD17: =D17*3+F17*2+H17*2+J17*2+N17*3+P17*2+R17*2+T17*2+V17*3+X17*2+Z17*2+AB17*2 -> 4 | AE17: =E17*3+G17*2+I17*2+K17*2+O17*3+Q17*2+S17*2+U17*2+W17*3+Y17*2+AA17*2+AC17*2 -> 4
C18: 初階英文閱讀與寫作練習 | J18: 2 | K18: 2 | AD18: =D18*3+F18*2+H18*2+J18*2+N18*3+P18*2+R18*2+T18*2+V18*3+X18*2+Z18*2+AB18*2 -> 4 | AE18: =E18*3+G18*2+I18*2+K18*2+O18*3+Q18*2+S18*2+U18*2+W18*3+Y18*2+AA18*2+AC18*2 -> 4
C19: 中階英語聽講練習 | T19: 2 | U19: 2 | AD19: =D19*3+F19*2+H19*2+J19*2+N19*3+P19*2+R19*2+T19*2+V19*3+X19*2+Z19*2+AB19*2 -> 4 | AE19: =E19*3+G19*2+I19*2+K19*2+O19*3+Q19*2+S19*2+U19*2+W19*3+Y19*2+AA19*2+AC19*2 -> 4
C20: 中階英文閱讀與寫作練習 | T20: 2 | U20: 2 | AD20: =D20*3+F20*2+H20*2+J20*2+N20*3+P20*2+R20*2+T20*2+V20*3+X20*2+Z20*2+AB20*2 -> 4 | AE20: =E20*3+G20*2+I20*2+K20*2+O20*3+Q20*2+S20*2+U20*2+W20*3+Y20*2+AA20*2+AC20*2 -> 4
C21: 高階英語聽講練習 | AB21: 2 | AC21: 2 | AD21: =D21*3+F21*2+H21*2+J21*2+N21*3+P21*2+R21*2+T21*2+V21*3+X21*2+Z21*2+AB21*2 -> 4 | AE21: =E21*3+G21*2+I21*2+K21*2+O21*3+Q21*2+S21*2+U21*2+W21*3+Y21*2+AA21*2+AC21*2 -> 4
C22: 高階英文閱讀與寫作練習 | AB22: 2 | AC22: 2 | AD22: =D22*3+F22*2+H22*2+J22*2+N22*3+P22*2+R22*2+T22*2+V22*3+X22*2+Z22*2+AB22*2 -> 4 | AE22: =E22*3+G22*2+I22*2+K22*2+O22*3+Q22*2+S22*2+U22*2+W22*3+Y22*2+AA22*2+AC22*2 -> 4
C23: 基礎英文閱讀與寫作 | N23: 2 | O23: 2 | P23: 2 | Q23: 2 | R23: 2 | S23: 2 | AD23: =D23*3+F23*2+H23*2+J23*2+N23*3+P23*2+R23*2+T23*2+V23*3+X23*2+Z23*2+AB23*2 -> 14 | AE23: =E23*3+G23*2+I23*2+K23*2+O23*3+Q23*2+S23*2+U23*2+W23*3+Y23*2+AA23*2+AC23*2 -> 14
C24: 英文商業書信寫作 | AB24: 2 | AD24: =D24*3+F24*2+H24*2+J24*2+N24*3+P24*2+R24*2+T24*2+V24*3+X24*2+Z24*2+AB24*2 -> 4 | AE24: =E24*3+G24*2+I24*2+K24*2+O24*3+Q24*2+S24*2+U24*2+W24*3+Y24*2+AA24*2+AC24*2 -> 0
C25: 英美文學作品賞析 | T25: 1 | AD25: =D25*3+F25*2+H25*2+J25*2+N25*3+P25*2+R25*2+T25*2+V25*3+X25*2+Z25*2+AB25*2 -> 2 | AE25: =E25*3+G25*2+I25*2+K25*2+O25*3+Q25*2+S25*2+U25*2+W25*3+Y25*2+AA25*2+AC25*2 -> 0
C26: 實用英文表達(AN選)5選1 | Q26: 2 | U26: 2 | AD26: =D26*3+F26*2+H26*2+J26*2+N26*3+P26*2+R26*2+T26*2+V26*3+X26*2+Z26*2+AB26*2 -> 0 | AE26: 2
C27: 英語導覽(AM選)2選1 | U27: 2 | AD27: 0 | AE27: 2
C28: 英語多媒體口說練習(AM選)2選1 | U28: 2 | AD28: 0 | AE28: 2
C29: 繪本製作(AK選)3選1 | T29: 2 | AD29: 2 | AE29: =E29*3+G29*2+I29*2+K29*2+O29*3+Q29*2+S29*2+U29*2+W29*3+Y29*2+AA29*2+AC29*2 -> 0
C30: 英語電影欣賞與討論(AK選)3選1 | T30: 2 | AD30: 2 | AE30: 0
C31: 英語桌遊(AK選)3選1 | T31: 2 | AD31: 2 | AE31: =E31*3+G31*2+I31*2+K31*2+O31*3+Q31*2+S31*2+U31*2+W31*3+Y31*2+AA31*2+AC31*2 -> 0
C32: 中英翻譯練習(AL選)2選1 | U32: 0 | AD32: =D32*3+F32*2+H32*2+J32*2+N32*3+P32*2+R32*2+T32*2+V32*3+X32*2+Z32*2+AB32*2 -> 0 | AE32: 2
C33: 趣味英文閱讀 | V33: 2 | W33: 2 | X33: 2 | Y33: 2 | Z33: 2 | AA33: 2 | AD33: =D33*3+F33*2+H33*2+J33*2+N33*3+P33*2+R33*2+T33*2+V33*3+X33*2+Z33*2+AB33*2 -> 14 | AE33: =E33*3+G33*2+I33*2+K33*2+O33*3+Q33*2+S33*2+U33*2+W33*3+Y33*2+AA33*2+AC33*2 -> 14
C34: 英文(彈性補強) | AD34: 1 | AE34: 1
C35: 新聞英文導讀 | T35: 1 | AD35: =D35*3+F35*2+H35*2+J35*2+N35*3+P35*2+R35*2+T35*2+V35*3+X35*2+Z35*2+AB35*2 -> 2 | AE35: =E35*3+G35*2+I35*2+K35*2+O35*3+Q35*2+S35*2+U35*2+W35*3+Y35*2+AA35*2+AC35*2 -> 0
C36: 觀光餐旅英語(AG選)2選1 | AC36: 2 | AD36: =AB36*2 -> 0 | AE36: 2
C37: 觀光餐旅英語(AL選)2選1 | U37: 0 | AD37: 0 | AE37: 0
C38: 英語導覽(AG選)2選1 | AC38: 2 | AD38: 0 | AE38: 2
C39: 外語簡報實務 | T39: 2 | U39: 2 | AD39: =T39*2 -> 4 | AE39: =U39*2 -> 4
C40: 外語文書處理實務 | J40: 2 | K40: 2 | AD40: =D40*3+F40*2+H40*2+J40*2+N40*3+P40*2+R40*2+T40*2+V40*3+X40*2+Z40*2+AB40*2 -> 4 | AE40: =E40*3+G40*2+I40*2+K40*2+O40*3+Q40*2+S40*2+U40*2+W40*3+Y40*2+AA40*2+AC40*2 -> 4
...

Sheet 進113課程節數一覽表
A1: ="國立花蓮高商進修部 113 學年度第 1 學期課程節數概算表" -> 國立花蓮高商進修部 113 學年度第 1 學期課程節數概算表 | K1: =TODAY() -> 45604
A2: 教學 領域 | B2: 年級科別 科目名稱 | C2: 一年級 | F2: 二 年 級 | H2: 三年級 | J2: 小 計 | K2: 總 計 | L2: 備 註 (現有正式教師) | M2: 導師
C3: 商經 | D3: 資處 | E3: 商訊 | F3: 商經 | G3: 資處 | H3: 商經 | I3: 資處
A4: 語文 | B4: 國語文 | C4: 2 | D4: 2 | E4: 3 | F4: 2 | G4: 2 | H4: 2 | I4: 2 | J4: =SUM(C4:I4) -> 15 | K4: =SUM(J4:J11) -> 29 | L4: 組長:李智淵(5)(課諮-1) 導師:顏如玉(10) 導師:許雅婷(10) | M4: 商一甲 | N4: 張萬華
B5: 本土語文 | C5: 1 | D5: 1 | E5: 1 | J5: =SUM(C5:I5) -> 3 | M5: 資一甲 | N5: 許雅婷
B6: 公民與社會 | C6: 1 | D6: 1 | E6: 1 | J6: =SUM(C6:I6) -> 3 | M6: 訊一甲 | N6: 顏如玉
B7: 歷史 | C7: 1 | D7: 1 | J7: =SUM(C7:I7) -> 2 | M7: 商二甲 | N7: 張美惠
B8: 從在地作家看經典 | H8: 1 | J8: =SUM(C8:I8) -> 1 | M8: 資二甲 | N8: 劉和師
B9: 彈性學習時間 | H9: 2 | I9: 2 | J9: =SUM(C9:I9) -> 4 | M9: 商三甲 | N9: 張秋菊
B10: 花蓮作家與原住民文學 | I10: 1 | J10: =SUM(C10:I10) -> 1 | M10: 資三甲 | N10: 黃文華
B11: 國語文閱讀寫作 | J11: =SUM(C11:I11) -> 0
A12: 英文 | B12: 英語文 | C12: 2 | D12: 2 | E12: 2 | F12: 2 | G12: 2 | H12: 2 | I12: 2 | J12: =SUM(C12:I12) -> 14 | K12: =SUM(J12:J13) -> 14 | L12: 導師:張萬華(12)
B13: 實用英語 | J13: =SUM(C13:I13) -> 0
A14: 數學 | B14: 數學 | C14: 2 | D14: 2 | E14: 2 | F14: 2 | G14: 2 | J14: =SUM(C14:I14) -> 10 | K14: =SUM(J14) -> 10 | L14: 組長:吳振銘(6)
A15: 會計科 | B15: 會計學 | C15: 3 | D15: 3 | F15: 2 | G15: 2 | J15: =SUM(C15:I15) -> 10 | K15: =SUM(J15:J27) -> 27 | L15: 導師:黃文華(12) 專任:黃伃延(16)
B16: 會計實務 | E16: 3 | H16: 2 | J16: =SUM(C16:I16) -> 5
B17: 行銷實務 | F17: 2 | J17: =SUM(C17:I17) -> 2
B18: 會計學概要分析 | H18: 2 | I18: 2 | J18: =SUM(C18:I18) -> 4
B19: 記帳實務 | J19: =SUM(C19:I19) -> 0
B20: 會計軟體應用 | J20: =SUM(C20:I20) -> 0
B21: 金融與證券投資實務 | H21: 2 | J21: =SUM(C21:I21) -> 2
B22: 活用會計(核跨班) | F22: 2 | H22: 2 | J22: =SUM(C22:I22) -> 4
B23: 帳務分析實作(核跨班) | J23: =SUM(C23:I23) -> 0
B24: 資訊記帳實務(核跨班) | J24: =SUM(C24:I24) -> 0
B25: 人工記帳實務(核跨班) | J25: =SUM(C25:I25) -> 0
B26: 會計實務進階(實選修) | J26: =SUM(C26:I26) -> 0
B27: 行銷實務(實選修) | J27: =SUM(C27:I27) -> 0
A28: 商經科 | B28: 商業概論 | C28: 2 | D28: 2 | E28: 2 | J28: =SUM(C28:I28) -> 6 | K28: =SUM(J28:J41) -> 24 | L28: 導師:張秋菊(12) 專任:李思穎(16)
B29: 門市經營實務 | C29: 2 | J29: =SUM(C29:I29) -> 2
B30: 門市服務實務 | E30: 3 | J30: =SUM(C30:I30) -> 3
B31: 商業刊物導讀 | J31: =SUM(C31:I31) -> 0
B32: 經濟學 | F32: 4 | G32: 2 | J32: =SUM(C32:I32) -> 6
B33: 經濟學概要 | J33: =SUM(C33:I33) -> 0
B34: 經濟學進階 | H34: 3 | J34: =SUM(C34:I34) -> 3
B35: 專題實作 | H35: 2 | J35: =SUM(C35:I35) -> 2
B36: 商業經營管理 | J36: =SUM(C36:I36) -> 0
B37: 商業簡報實務(核跨班) | H37: 2 | J37: =SUM(C37:I37) -> 2
B38: 理財桌遊(核跨班) | J38: =SUM(C38:I38) -> 0
B39: 電子商務實務(實選修) | J39: =SUM(C39:I39) -> 0
B40: 商業簡報實務(實選修) | J40: =SUM(C40:I40) -> 0
...

Sheet 113進修部-節數比較表(7班)
A1: 進修部--課程時數概算比較表
A2: 學年度 | B2: 113-1學年度(預估) | F2: 平均兼課時數 | I2: 113 上學年度
A3: 群別 | B3: 基本 節數 | C3: 分配 節數 | D3: 剩餘 節數 | F3: 113學年度 | I3: 職稱 | J3: 主任 | K3: 組長 | M3: 科主任 | O3: 導師 | R3: 專任 | U3: 兼課 | V3: 教官 | W3: 合 計 | X3: 基本授課 時數
I4: 基本 時數 | J4: 5 | K4: 6 | L4: 7 | M4: 7 | N4: =SUM(M4:M10) -> 7 | O4: 10 | P4: 12 | Q4: 14 | R4: 14 | S4: 16 | T4: 18 | U4: 0 | V4: 10
A5: 國文/ 社會領域 | B5: =X5 -> 25 | C5: ='[1]113-1_7班'!L4 -> 29 | D5: =C5-B5+1 -> 5 | F5: =IF(W5=0,D5,D5/(W5-U5)) -> 1.6666667 | G5: 節/人 | I5: 各科教師人數 | K5: 1 | O5: 2 | W5: =SUM(J5:V5) -> 3 | X5: =$J$4*J5+$K$4*K5+$L$4*L5+$M$4*M5+$N$4*N5+$O$4*O5+$P$4*P5+$Q$4*Q5+$R$4*R5+$S$4*S5+$T$4*T5+$U$4*U5+$V$4*V5-1 -> 25 | Y5: 組長：李智淵(5)(課諮減1) 導師：許雅婷(10) 導師：顏如玉(10) | Z5: 本土-3 +3班會
A6: 英文領域 | B6: =X6 -> 12 | C6: ='[1]113-1_7班'!L12 -> 14 | D6: =C6-B6 -> 2 | F6: =IF(W6=0,D6,D6/(W6-U6)) -> 2 | G6: 節/人 | P6: 1 | W6: =SUM(J6:V6) -> 1 | X6: =$J$4*J6+$K$4*K6+$L$4*L6+$M$4*M6+$N$4*N6+$O$4*O6+$P$4*P6+$Q$4*Q6+$R$4*R6+$S$4*S6+$T$4*T6+$U$4*U6+$V$4*V6 -> 12
A7: 數學領域 | B7: =X7 -> 14 | C7: ='[1]113-1_7班'!L14 -> 10 | D7: =C7-B7 -> -4 | F7: =IF(W7=0,D7,D7/(W7-U7)) -> -4 | G7: 節/人 | R7: 1 | W7: =SUM(J7:V7) -> 1 | X7: =$J$4*J7+$K$4*K7+$L$4*L7+$M$4*M7+$N$4*N7+$O$4*O7+$P$4*P7+$Q$4*Q7+$R$4*R7+$S$4*S7+$T$4*T7+$U$4*U7+$V$4*V7 -> 14
A8: 自然領域 | B8: =X8 -> 0 | C8: ='[1]113-1_7班'!L68 -> 4 | D8: =C8-B8 -> 4 | F8: =IF(W8=0,D8,D8/(W8-U8)) -> 4 | G8: 節/人 | W8: =SUM(J8:V8) -> 0 | X8: =$J$4*J8+$K$4*K8+$L$4*L8+$M$4*M8+$N$4*N8+$O$4*O8+$P$4*P8+$Q$4*Q8+$R$4*R8+$S$4*S8+$T$4*T8+$U$4*U8+$V$4*V8 -> 0
A9: 會計科 | B9: =X9 -> 12 | C9: ='[1]113-1_7班'!L15 -> 27 | D9: =C9-B9+1 -> 16 | F9: =IF(W9=0,D9,D9/(W9-U9)) -> 16 | G9: 節/人 | P9: 1 | W9: =SUM(J9:V9) -> 1 | X9: =$J$4*J9+$K$4*K9+$L$4*L9+$M$4*M9+$N$4*N9+$O$4*O9+$P$4*P9+$Q$4*Q9+$R$4*R9+$S$4*S9+$T$4*T9+$U$4*U9+$V$4*V9 -> 12 | Y9: 導師：黃文華(12) | Z9: +1班會
A10: 商經科 | B10: =X10 -> 12 | C10: ='[1]113-1_7班'!L28 -> 24 | D10: =C10-B10+1 -> 13 | F10: =IF(W10=0,D10,D10/(W10-U10)) -> 13 | G10: 節/人 | P10: 1 | W10: =SUM(J10:V10) -> 1 | X10: =$J$4*J10+$K$4*K10+$L$4*L10+$M$4*M10+$N$4*N10+$O$4*O10+$P$4*P10+$Q$4*Q10+$R$4*R10+$S$4*S10+$T$4*T10+$U$4*U10+$V$4*V10 -> 12 | Y10: 導師：張秋菊(12) | Z10: +1班會
A11: 資處科 | B11: =X11 -> 29 | C11: ='[1]113-1_7班'!L42 -> 35 | D11: =C11-B11+2 -> 8 | F11: =IF(W11=0,D11,D11/(W11-U11)) -> 2.6666667 | G11: 節/人 | J11: 1 | P11: 2 | W11: =SUM(J11:V11) -> 3 | X11: =$J$4*J11+$K$4*K11+$L$4*L11+$M$4*M11+$N$4*N11+$O$4*O11+$P$4*P11+$Q$4*Q11+$R$4*R11+$S$4*S11+$T$4*T11+$U$4*U11+$V$4*V11 -> 29 | Y11: 主任：官孟璋(5) 導師：劉和師(12) 導師：張美惠(12) | Z11: +2班會
A12: 藝術與生活 | B12: =X12 -> 0 | C12: ='[1]113-1_7班'!L63 -> 4 | D12: =C12-B12 -> 4 | F12: =IF(W12=0,D12,D12/(W12-U12)) -> 4 | G12: 節/人 | W12: =SUM(J12:V12) -> 0 | X12: =$J$4*J12+$K$4*K12+$L$4*L12+$M$4*M12+$N$4*N12+$O$4*O12+$P$4*P12+$Q$4*Q12+$R$4*R12+$S$4*S12+$T$4*T12+$U$4*U12+$V$4*V12 -> 0
A13: 體育 | B13: =X13 -> 0 | C13: ='[1]113-1_7班'!K70+'[1]113-1_7班'!K71 -> 7 | D13: =C13-B13 -> 7 | F13: =IF(W13=0,D13,D13/(W13-U13)) -> 7 | G13: 節/人 | W13: =SUM(J13:V13) -> 0 | X13: =$J$4*J13+$K$4*K13+$L$4*L13+$M$4*M13+$N$4*N13+$O$4*O13+$P$4*P13+$Q$4*Q13+$R$4*R13+$S$4*S13+$T$4*T13+$U$4*U13+$V$4*V13 -> 0
A14: 健康與護理 | B14: =X14 -> 0 | C14: ='[1]113-1_7班'!K72 -> 2 | D14: =C14-B14 -> 2 | F14: =IF(W14=0,D14,D14/(W14-U14)) -> 2 | G14: 節/人 | W14: =SUM(J14:V14) -> 0 | X14: =$J$4*J14+$K$4*K14+$L$4*L14+$M$4*M14+$N$4*N14+$O$4*O14+$P$4*P14+$Q$4*Q14+$R$4*R14+$S$4*S14+$T$4*T14+$U$4*U14+$V$4*V14 -> 0
A15: 國防通識/ 全民國防教育 | B15: =X15 -> 0 | C15: ='[1]113-1_7班'!K73 -> 2 | D15: =C15-B15 -> 2 | F15: =IF(W15=0,D15,D15/(W15-U15)) -> 2 | G15: 節/人 | W15: =SUM(J15:V15) -> 0 | X15: =$J$4*J15+$K$4*K15+$L$4*L15+$M$4*M15+$N$4*N15+$O$4*O15+$P$4*P15+$Q$4*Q15+$R$4*R15+$S$4*S15+$T$4*T15+$U$4*U15+$V$4*V15 -> 0
A16: 輔導 | B16: =X16 -> 6 | C16: ='[1]113-1_7班'!L65 -> 3 | D16: =C16-B16 -> -3 | F16: =IF(W16=0,D16,D16/(W16-U16)) -> -3 | G16: 節/人 | K16: 1 | W16: =SUM(J16:V16) -> 1 | X16: =$J$4*J16+$K$4*K16+$L$4*L16+$M$4*M16+$N$4*N16+$O$4*O16+$P$4*P16+$Q$4*Q16+$R$4*R16+$S$4*S16+$T$4*T16+$U$4*U16+$V$4*V16 -> 6 | Y16: 輔導老師：黃佩莉(6)
A17: 團體活動 | B17: =X17 -> 0 | C17: ='[1]113-1_7班'!K75 -> 8 | D17: =C17-B17-7 -> 1 | F17: =IF(W17=0,D17,D17/(W17-U17)) -> 1 | G17: 節/人 | W17: =SUM(J17:V17) -> 0 | X17: =$J$4*J17+$K$4*K17+$L$4*L17+$M$4*M17+$N$4*N17+$O$4*O17+$P$4*P17+$Q$4*Q17+$R$4*R17+$S$4*S17+$T$4*T17+$U$4*U17+$V$4*V17 -> 0 | Y17: 導師
B18: =SUM(B5:B17) -> 110 | C18: =SUM(C5:C17) -> 169 | D18: =SUM(D5:D17) -> 57
